Workbook

Sheet 00 · How to use
A1: SIMF — Production-Readiness Test Book
A2: Generated from docs/tests/e2e/*.md + SIMF-Business-Flows.md by tools/testbook/build_testbook.py. Do not hand-edit test rows — re-run the script.
A4: How to run
A5: 1. Bring up the local stack (Test-Guide.md §12.2): API :5175, Control Panel :5158, Website :5115; wait for GET /health → 200.
A6: 2. Sign in as the seeded super-admin (password + TOTP via the Get-Totp helper). Never write a literal secret into this workbook.
A7: 3. Work sheet by sheet. For each row: perform the Test, then fill Comment / Time (min) / Status / Developer comment / Evidence.
A8: 4. Business Flows (sheet 02) and Cross-cutting (sheet 06) carry the full Gherkin steps inline. Per-page sheets (03/04/05) link to the canonical .md in the 'Catalogue ref' column for the full steps.
A9: 5. Log every bug on sheet 07 · Defect log with a severity, root cause and the fix commit.
A11: Status legend
A12: Not Run — not yet executed. Pass — matched the expected result. Fail — deviated (log a defect). Blocked — could not run (dependency/environment). N/A — not applicable to this build (e.g. a deferred feature).
A14: Priority
A15: P0 — must pass to ship (golden paths, auth/permission gates). P1 — must pass for a release. P2 — resilience/edge; exercised once per release window.
... A18: Deferred features (attendee-facing geofence check-in; exact statistics metric list; dynamic session-category list) and provider stubs (live-video; AI question-filter) are marked N/A, not Fail. See SIMF-Production-Readiness-Round1.md §2.2 and §7.

Sheet 01 · Summary
A1: SIMF Production-Readiness — run summary
A2: Live roll-up over the Status columns. Updates as the tester fills each sheet.
A4: Sheet | B4: Total | C4: Not Run | D4: Pass | E4: Fail | F4: Blocked | G4: N/A | H4: % Pass
A5: 02 · Business Flows | B5: 115 | C5: =COUNTIF('02 · Business Flows'!N2:N116,"Not Run") | D5: =COUNTIF('02 · Business Flows'!N2:N116,"Pass") | E5: =COUNTIF('02 · Business Flows'!N2:N116,"Fail") | F5: =COUNTIF('02 · Business Flows'!N2:N116,"Blocked") | G5: =COUNTIF('02 · Business Flows'!N2:N116,"N/A") | H5: =IFERROR(D5/(B5-G5),0)
A6: 03 · Control Panel | B6: 1377 | C6: =COUNTIF('03 · Control Panel'!N2:N1378,"Not Run") | D6: =COUNTIF('03 · Control Panel'!N2:N1378,"Pass") | E6: =COUNTIF('03 · Control Panel'!N2:N1378,"Fail") | F6: =COUNTIF('03 · Control Panel'!N2:N1378,"Blocked") | G6: =COUNTIF('03 · Control Panel'!N2:N1378,"N/A") | H6: =IFERROR(D6/(B6-G6),0)
A7: 04 · Website | B7: 153 | C7: =COUNTIF('04 · Website'!N2:N154,"Not Run") | D7: =COUNTIF('04 · Website'!N2:N154,"Pass") | E7: =COUNTIF('04 · Website'!N2:N154,"Fail") | F7: =COUNTIF('04 · Website'!N2:N154,"Blocked") | G7: =COUNTIF('04 · Website'!N2:N154,"N/A") | H7: =IFERROR(D7/(B7-G7),0)
A8: 05 · Mobile App | B8: 618 | C8: =COUNTIF('05 · Mobile App'!N2:N619,"Not Run") | D8: =COUNTIF('05 · Mobile App'!N2:N619,"Pass") | E8: =COUNTIF('05 · Mobile App'!N2:N619,"Fail") | F8: =COUNTIF('05 · Mobile App'!N2:N619,"Blocked") | G8: =COUNTIF('05 · Mobile App'!N2:N619,"N/A") | H8: =IFERROR(D8/(B8-G8),0)
A9: 06 · Cross-cutting | B9: 79 | C9: =COUNTIF('06 · Cross-cutting'!N2:N80,"Not Run") | D9: =COUNTIF('06 · Cross-cutting'!N2:N80,"Pass") | E9: =COUNTIF('06 · Cross-cutting'!N2:N80,"Fail") | F9: =COUNTIF('06 · Cross-cutting'!N2:N80,"Blocked") | G9: =COUNTIF('06 · Cross-cutting'!N2:N80,"N/A") | H9: =IFERROR(D9/(B9-G9),0)
A10: TOTAL | B10: =SUM(B5:B9) | C10: =SUM(C5:C9) | D10: =SUM(D5:D9) | E10: =SUM(E5:E9) | F10: =SUM(F5:F9) | G10: =SUM(G5:G9) | H10: =IFERROR(D10/(B10-G10),0)

Sheet 02 · Business Flows
A1: ID | B1: Surface | C1: Area / Flow | D1: Page / Route | E1: Test (scenario) | F1: Steps / Gherkin | G1: Test data | H1: Expected result | I1: Priority | J1: Type | K1: Catalogue ref | L1: Comment | M1: Time (min) | N1: Status | O1: Developer comment | P1: Evidence
A2: E2E-BF-01-001 | B2: CP/App | C2: BF-01 Bulk delegation onboarding → badge activation | E2: Golden journey: bulk-generate the China delegation (1 VVIP + 5 VIP + 50 Normal) → holder scans a Normal badge → activate (supply email → code → first password) → badge sign-in | F2: Feature: Bulk delegation onboarding then badge activation Background: Given the API is reachable on http://localhost:5175 And the Control Panel is reachable on http://localhost:5158 And an Administrator is signed in (password + TOTP via the Get-Totp helper) And the audience ProfileTypes "VVIP", "VIP" and "Normal" exist with IsActive=true and IsForVisitor=true Scenario: Mint the China delegation and let a member claim their badge Given the administrator opens /admin/delegates And the bulk-generate panel renders one count field per active audience ProfileType And the "Mark as delegation members" checkbox (_bulkIsDelegate) is checked by default When they enter VVIP=1, VIP=5, Normal=50 And they click "Generate badges" Then the CP posts /account/api/admin/visitors/bulk-generate with IsDelegate=true And the backend POST /api/v1/admin/visitors/bulk-generate returns ApiResult.Ok And AdminBulkGenerateBadgesResponse.Created = 56 And a bilingual SimfAlert success reports 56 badges generated And every new SimfUser has AccountState=Approved, UserType=Visitor, EmailConfirmed=true, a badge-{guid}@simf.local login and NO password And every new UserProfile has IsDelegate=true, NationalityId=0 and a minted QR id And an OperationLog row records AdminBulkBadgesGenerated for the actor with created=56; isDelegate=True Given a delegate holds one printed "Normal" badge for that batch When the mobile app posts /api/v1/app/auth/resolve-badge with that badge's QrId Then ResolveBadgeResponse.Found=true, HasPassword=false, NeedsEmail=true, MaskedEmail=null And the app shows the activation screen with the holder's DisplayName (e.g. "Normal #7") When the holder enters "khalid.demo@example.com" and the app posts /api/v1/app/auth/badge-activation/start Then a 6-digit code is emailed and BadgeActivationStartResponse returns the masked email + CodeExpiresInSeconds=600 When the tester reads the latest BadgeActivationOtp code from SIMF_Identity.AccountCodes for that user And the app posts /api/v1/app/auth/badge-activation/complete with that code + a first password that meets policy Then BadgeActivationCompleteResponse.Activated=true and the account's email is now confirmed When the app posts /api/v1/app/auth/badge-sign-in with the QrId + that password Then a standard SignInResponse (tokens or the 2FA challenge) is returned and the holder is signed in | I2: P0 | J2: happy | K2: SIMF-Business-Flows.md | N2: Not Run
A3: E2E-BF-01-002 | B3: CP/App | C3: BF-01 Bulk delegation onboarding → badge activation | E3: Second, smaller delegation (Ministry of Interior: 3 VIP + 7 Normal) mints 10 badges with per-tier display names | F3: Scenario: Ministry of Interior delegation mints 10 badges Given the administrator is on /admin/delegates When they enter VIP=3, Normal=7 and keep _bulkIsDelegate checked And they click "Generate badges" Then AdminBulkGenerateBadgesResponse.Created = 10 And the generated display names follow "{ProfileType.Name} #{n}" using the request-wide running counter And each of the 10 UserProfiles carries IsDelegate=true and its own minted QR And the visitor walk-in flow above the panel is untouched (the delegates desk is a separate page) | I3: P1 | J3: happy | K3: SIMF-Business-Flows.md | N3: Not Run
A4: E2E-BF-01-003 | B4: CP/App | C4: BF-01 Bulk delegation onboarding → badge activation | E4: Permission gate: admin without `Visitors.BulkGenerate` cannot see or call the bulk panel; page gate `Visitors.RegisterOnsite` blocks the whole desk | F4: Scenario: The bulk panel is hidden and refused without Visitors.BulkGenerate Given a signed-in admin whose role grants Visitors.RegisterOnsite but NOT Visitors.BulkGenerate When they open /admin/delegates Then the single-delegate registration form renders But the bulk-generate panel is not rendered (wrapped in AuthorizedAction Permission="Visitors.BulkGenerate") When they replay POST /api/v1/admin/visitors/bulk-generate directly Then the API returns HTTP 403 (endpoint Policies gate = Visitors.BulkGenerate + RequireApprovedAccount) Scenario: The whole delegates desk is gated by Visitors.RegisterOnsite Given a signed-in admin whose role grants neither permission When they navigate to /admin/delegates Then they are redirected to /not-permitted with HTTP 200 | I4: P0 | J4: auth | K4: SIMF-Business-Flows.md | N4: Not Run
A5: E2E-BF-01-004 | B5: CP/App | C5: BF-01 Bulk delegation onboarding → badge activation | E5: "At least one positive batch" rule: all counts 0 / empty batches → `VALIDATION_FAILED` | F5: Scenario: Empty / all-zero batches are rejected Given the administrator is on /admin/delegates When they leave every count at 0 (or send no batches with Count > 0) And they click "Generate badges" Then the backend returns ApiResult.Error with Code = "VALIDATION_FAILED" (HTTP 400) And a bilingual SimfAlert error reads "Provide at least one batch with a positive count." / "أدخل دفعة واحدة على الأقل بعدد موجب." And no badge accounts are created | I5: P1 | J5: error | K5: SIMF-Business-Flows.md | N5: Not Run
A6: E2E-BF-01-005 | B6: CP/App | C6: BF-01 Bulk delegation onboarding → badge activation | E6: `MaxPerRequest` cap: batches summing to 1001 → `VALIDATION_FAILED` "At most 1000 badges…" | F6: Scenario: A request over the 1000-badge cap is rejected wholesale Given the administrator is on /admin/delegates When they enter VVIP=1 and Normal=1000 (sum = 1001) And they click "Generate badges" Then the backend returns ApiResult.Error with Code = "VALIDATION_FAILED" (HTTP 400) And a bilingual SimfAlert error reads "At most 1000 badges can be generated per request." And zero badges are created (the cap is checked before the mint loop starts) | I6: P1 | J6: error | K6: SIMF-Business-Flows.md | N6: Not Run
A7: E2E-BF-01-006 | B7: CP/App | C7: BF-01 Bulk delegation onboarding → badge activation | E7: Least-privilege guard: a partner / elevated ProfileType (`IsForVisitor==false`) is refused → `ADMIN_PROFILE_TYPE_INVALID` | F7: Scenario: A non-visitor ProfileType cannot be bulk-generated Given a ProfileType "Media Partner" exists with IsActive=true and IsForVisitor=false And a caller submits a batch { ProfileTypeId = <Media Partner id>, Count = 10 } to POST /api/v1/admin/visitors/bulk-generate When the backend processes that batch Then it returns ApiResult.Error with Code = "ADMIN_PROFILE_TYPE_INVALID" (HTTP 400) And a bilingual error reads "Bulk-generate is only available for audience (visitor) profile types." And no badge is created for that batch # Note: the CP panel only renders count fields for IsForVisitor==true types, so this is an API-level guard against a smuggled ProfileTypeId. | I7: P0 | J7: error | K7: SIMF-Business-Flows.md | N7: Not Run
A8: E2E-BF-01-007 | B8: CP/App | C8: BF-01 Bulk delegation onboarding → badge activation | E8: Inactive / unknown ProfileType id → `ADMIN_PROFILE_TYPE_INVALID` "The selected profile type is not valid." | F8: Scenario: An inactive or unknown ProfileType id is rejected Given a batch references a ProfileTypeId that is not IsActive (or does not exist) When POST /api/v1/admin/visitors/bulk-generate processes it Then it returns ApiResult.Error with Code = "ADMIN_PROFILE_TYPE_INVALID" (HTTP 400) And a bilingual error reads "The selected profile type is not valid." / "نوع الملف الشخصي المحدّد غير صالح." | I8: P2 | J8: error | K8: SIMF-Business-Flows.md | N8: Not Run
A9: E2E-BF-01-008 | B9: CP/App | C9: BF-01 Bulk delegation onboarding → badge activation | E9: Badge already activated: a badge that already has a password → activation start → `BADGE_ALREADY_ACTIVATED` (409) | F9: Scenario: Starting activation on a badge that already has a password is refused Given a badge account that has already completed activation (it now has a password) When the app posts /api/v1/app/auth/badge-activation/start for that QrId Then the API returns ApiResult.Error with Code = "BADGE_ALREADY_ACTIVATED" (HTTP 409) And the message reads "This account already has a password. Sign in with your email and password." And the app routes the holder to normal badge sign-in instead | I9: P1 | J9: error | K9: SIMF-Business-Flows.md | N9: Not Run
A10: E2E-BF-01-009 | B10: CP/App | C10: BF-01 Bulk delegation onboarding → badge activation | E10: Activation code expired / wrong: complete with an expired or wrong code → `AUTH_RESET_CODE_EXPIRED` / `AUTH_RESET_CODE_INVALID` (5-attempt cap) | F10: Scenario: An expired activation code is rejected Given a badge holder started activation more than 10 minutes ago (CodeLifetime elapsed) When they post /api/v1/app/auth/badge-activation/complete with the now-expired code Then the API returns ApiResult.Error with Code = "AUTH_RESET_CODE_EXPIRED" (HTTP 400) And the message reads "The verification code has expired. Request a new one." Scenario: A wrong code is rejected and burns an attempt Given a badge holder has a valid, unconsumed activation code When they post /badge-activation/complete with an incorrect 6-digit code Then the API returns ApiResult.Error with Code = "AUTH_RESET_CODE_INVALID" (HTTP 400) And the AccountCode AttemptCount is incremented When they submit 5 wrong codes in total Then every further attempt on that code returns "AUTH_RESET_CODE_INVALID" (MaxAttempts = 5) | I10: P1 | J10: error | K10: SIMF-Business-Flows.md | N10: Not Run
A11: E2E-BF-01-010 | B11: CP/App | C11: BF-01 Bulk delegation onboarding → badge activation | E11: Badge sign-in with an unknown / passwordless QR is indistinguishable from a wrong password → `AUTH_INVALID_CREDENTIALS` (401) | F11: Scenario: An unknown badge is indistinguishable from a wrong password Given a QrId that resolves to no approved account (or a passwordless badge that has not been activated) When the app posts /api/v1/app/auth/badge-sign-in with that QrId + any password Then the API returns ApiResult.Error with Code = "AUTH_INVALID_CREDENTIALS" (HTTP 401) And the message reads "The email address or password is not correct." (generic, no valid-QR oracle) And a SignInBadCredentials audit row is written with Detail = "badge" | I11: P1 | J11: auth | K11: SIMF-Business-Flows.md | N11: Not Run
A12: E2E-BF-01-011 | B12: CP/App | C12: BF-01 Bulk delegation onboarding → badge activation | E12: Email collision on activation: holder supplies an email already used by another account → `AUTH_EMAIL_ALREADY_REGISTERED` (409) | F12: Scenario: A holder tries to attach an email already in use Given a placeholder badge (badge-{guid}@simf.local, NeedsEmail=true) is being activated And another distinct account already owns "khalid.demo@example.com" When the app posts /api/v1/app/auth/badge-activation/start with Email="khalid.demo@example.com" Then the API returns ApiResult.Error with Code = "AUTH_EMAIL_ALREADY_REGISTERED" (HTTP 409) And the message reads "That email address is already in use." / "البريد الإلكتروني مستخدم بالفعل." And no verification code is emailed | I12: P2 | J12: error | K12: SIMF-Business-Flows.md | N12: Not Run
A13: E2E-BF-01-012 | B13: CP/App | C13: BF-01 Bulk delegation onboarding → badge activation | E13: Resilience: no cross-store transaction (D-157) — a mid-loop failure can leave a `SimfUser` (Identity) without a `UserProfile` (App) | F13: Scenario: A mid-loop failure can leave an Identity user without an App profile Given a bulk-generate request for VVIP=1 + Normal=50 And the App DB write for one badge's UserProfile fails part-way through the loop When the request aborts Then the SimfUser rows already committed to SIMF_Identity remain (each badge is created then saved individually — no distributed transaction, D-157) And the failing badge may have a SimfUser with NO matching UserProfile in SIMF_App And the response surfaces the partial count / error while the already-minted badges stay valid # Tester assertion: count SimfUsers with UserName like 'badge-%@simf.local' that have no UserProfile row, and flag any as an onboarding-resilience gap. | I13: P2 | J13: resilience | K13: SIMF-Business-Flows.md | N13: Not Run
... A116: E2E-BF-09-012 | B116: CP/Web/App | C116: BF-09 Close the year / snapshot-to-archive ("history this year") | E116: RTL/bilingual render of CP archive list + app archive screen (`سيمف 2026`) | F116: Scenario: RTL and bilingual render of the archived edition Given the UI language is Arabic (dir = rtl) And a 2026 edition exists with TitleAr "سيمف 2026" When the admin views the CP archive grid at "/admin/archive" Then the Arabic title "سيمف 2026" renders right-to-left with correct column mirroring And scrollWidth equals clientWidth (no horizontal overflow) with no broken thumbnails When a visitor opens the archive on the app (archive_screen.dart) in Arabic Then the past edition card shows the Arabic title, summary and counters in RTL order | I116: P1 | J116: i18n | K116: SIMF-Business-Flows.md | N116: Not Run

Sheet 03 · Control Panel
A1: ID | B1: Surface | C1: Area / Flow | D1: Page / Route | E1: Test (scenario) | F1: Steps / Gherkin | G1: Test data | H1: Expected result | I1: Priority | J1: Type | K1: Catalogue ref | L1: Comment | M1: Time (min) | N1: Status | O1: Developer comment | P1: Evidence
A2: E2E-NTF-001 | B2: Control Panel | C2: Control Panel — Account & auth (not in main nav) | D2: /account/notifications | E2: Golden round-trip | I2: P0 | J2: happy | K2: cp-account-notifications.md | N2: Not Run
A3: E2E-NTF-002 | B3: Control Panel | C3: Control Panel — Account & auth (not in main nav) | D3: /account/notifications | E3: Per-row Details modal | I3: P1 | J3: happy | K3: cp-account-notifications.md | N3: Not Run
A4: E2E-NTF-003 | B4: Control Panel | C4: Control Panel — Account & auth (not in main nav) | D4: /account/notifications | E4: Per-row Delete | I4: P1 | J4: happy | K4: cp-account-notifications.md | N4: Not Run
A5: E2E-NTF-004 | B5: Control Panel | C5: Control Panel — Account & auth (not in main nav) | D5: /account/notifications | E5: Multiselect + bulk Delete | I5: P1 | J5: happy | K5: cp-account-notifications.md | N5: Not Run
A6: E2E-NTF-005 | B6: Control Panel | C6: Control Panel — Account & auth (not in main nav) | D6: /account/notifications | E6: Mark all as read | I6: P0 | J6: happy | K6: cp-account-notifications.md | N6: Not Run
A7: E2E-NTF-006 | B7: Control Panel | C7: Control Panel — Account & auth (not in main nav) | D7: /account/notifications | E7: Empty inbox | I7: P1 | J7: happy | K7: cp-account-notifications.md | N7: Not Run
A8: E2E-NTF-007 | B8: Control Panel | C8: Control Panel — Account & auth (not in main nav) | D8: /account/notifications | E8: Filter / search no-match | I8: P2 | J8: edge | K8: cp-account-notifications.md | N8: Not Run
A9: E2E-NTF-008 | B9: Control Panel | C9: Control Panel — Account & auth (not in main nav) | D9: /account/notifications | E9: Pager | I9: P2 | J9: happy | K9: cp-account-notifications.md | N9: Not Run
A10: E2E-NTF-009 | B10: Control Panel | C10: Control Panel — Account & auth (not in main nav) | D10: /account/notifications | E10: Auth gate (unauthenticated) | I10: P0 | J10: auth | K10: cp-account-notifications.md | N10: Not Run
A11: E2E-NTF-010 | B11: Control Panel | C11: Control Panel — Account & auth (not in main nav) | D11: /account/notifications | E11: Idempotent re-delete | I11: P2 | J11: resilience | K11: cp-account-notifications.md | N11: Not Run
A12: E2E-NTF-011 | B12: Control Panel | C12: Control Panel — Account & auth (not in main nav) | D12: /account/notifications | E12: Server 500 on `/list` | I12: P2 | J12: resilience | K12: cp-account-notifications.md | N12: Not Run
A13: E2E-NTF-012 | B13: Control Panel | C13: Control Panel — Account & auth (not in main nav) | D13: /account/notifications | E13: RTL / Arabic render | I13: P1 | J13: i18n | K13: cp-account-notifications.md | N13: Not Run
... A412: E2E-EXH-024 | B412: Control Panel | C412: Control Panel — Exhibition | D412: /admin/exhibitors | E412: Excel round-trips the tier (D-503) | I412: P1 | J412: happy | K412: cp-admin-exhibitors.md | N412: Not Run
A413: E2E-FAQ-001 | B413: Control Panel | D413: /admin/faq | E413: Group CRUD round-trip | I413: P0 | J413: happy | K413: cp-admin-faq.md | N413: Not Run
A414: E2E-FAQ-002 | B414: Control Panel | D414: /admin/faq | E414: Entry CRUD round-trip | I414: P0 | J414: happy | K414: cp-admin-faq.md | N414: Not Run
A415: E2E-FAQ-003 | B415: Control Panel | D415: /admin/faq | E415: Manage entries selects a group | I415: P1 | J415: happy | K415: cp-admin-faq.md | N415: Not Run
A416: E2E-FAQ-004 | B416: Control Panel | D416: /admin/faq | E416: Empty groups state | I416: P1 | J416: happy | K416: cp-admin-faq.md | N416: Not Run
A417: E2E-FAQ-005 | B417: Control Panel | D417: /admin/faq | E417: Empty entries state | I417: P1 | J417: happy | K417: cp-admin-faq.md | N417: Not Run
A418: E2E-FAQ-006 | B418: Control Panel | D418: /admin/faq | E418: Entry count column reflects active entries | I418: P2 | J418: happy | K418: cp-admin-faq.md | N418: Not Run
A419: E2E-FAQ-007 | B419: Control Panel | D419: /admin/faq | E419: Auth gate (page permission) | I419: P0 | J419: auth | K419: cp-admin-faq.md | N419: Not Run
A420: E2E-FAQ-008 | B420: Control Panel | D420: /admin/faq | E420: Action gate (read-only admin) | I420: P1 | J420: auth | K420: cp-admin-faq.md | N420: Not Run
A421: E2E-FAQ-009 | B421: Control Panel | D421: /admin/faq | E421: Group validation: blank name | I421: P1 | J421: error | K421: cp-admin-faq.md | N421: Not Run
A422: E2E-FAQ-010 | B422: Control Panel | D422: /admin/faq | E422: Group validation: negative display order | I422: P1 | J422: error | K422: cp-admin-faq.md | N422: Not Run
A423: E2E-FAQ-011 | B423: Control Panel | D423: /admin/faq | E423: Entry validation: blank / over-length text | I423: P1 | J423: error | K423: cp-admin-faq.md | N423: Not Run
A424: E2E-FAQ-012 | B424: Control Panel | D424: /admin/faq | E424: Not-found on stale edit | I424: P2 | J424: error | K424: cp-admin-faq.md | N424: Not Run
... A427: E2E-FAQ-015 | B427: Control Panel | D427: /admin/faq | E427: RTL / Arabic render | I427: P1 | J427: i18n | K427: cp-admin-faq.md | N427: Not Run
A428: E2E-GDS-001 | B428: Control Panel | C428: Control Panel — Access control & system | D428: /admin/gates/dashboard | E428: Golden path | I428: P0 | J428: happy | K428: cp-admin-gates-dashboard.md | N428: Not Run
A429: E2E-GDS-002 | B429: Control Panel | C429: Control Panel — Access control & system | D429: /admin/gates/dashboard | E429: Refresh re-fires both calls | I429: P0 | J429: happy | K429: cp-admin-gates-dashboard.md | N429: Not Run
A430: E2E-GDS-003 | B430: Control Panel | C430: Control Panel — Access control & system | D430: /admin/gates/dashboard | E430: Stat cards agree with table counts | I430: P1 | J430: happy | K430: cp-admin-gates-dashboard.md | N430: Not Run
A431: E2E-GDS-004 | B431: Control Panel | C431: Control Panel — Access control & system | D431: /admin/gates/dashboard | E431: Empty *Currently inside* roster | I431: P1 | J431: happy | K431: cp-admin-gates-dashboard.md | N431: Not Run
A432: E2E-GDS-005 | B432: Control Panel | C432: Control Panel — Access control & system | D432: /admin/gates/dashboard | E432: Empty *Gates* roster | I432: P1 | J432: happy | K432: cp-admin-gates-dashboard.md | N432: Not Run
A433: E2E-GDS-006 | B433: Control Panel | C433: Control Panel — Access control & system | D433: /admin/gates/dashboard | E433: Active / Inactive pill rendering | I433: P1 | J433: happy | K433: cp-admin-gates-dashboard.md | N433: Not Run
A434: E2E-GDS-007 | B434: Control Panel | C434: Control Panel — Access control & system | D434: /admin/gates/dashboard | E434: Auth gate | I434: P0 | J434: auth | K434: cp-admin-gates-dashboard.md | N434: Not Run
A435: E2E-GDS-008 | B435: Control Panel | C435: Control Panel — Access control & system | D435: /admin/gates/dashboard | E435: Server 500 on `/currently-inside` | I435: P2 | J435: resilience | K435: cp-admin-gates-dashboard.md | N435: Not Run
A436: E2E-GDS-009 | B436: Control Panel | C436: Control Panel — Access control & system | D436: /admin/gates/dashboard | E436: Server 500 on `/gates/list` | I436: P2 | J436: resilience | K436: cp-admin-gates-dashboard.md | N436: Not Run
A437: E2E-GDS-010 | B437: Control Panel | C437: Control Panel — Access control & system | D437: /admin/gates/dashboard | E437: Loading state | I437: P2 | J437: happy | K437: cp-admin-gates-dashboard.md | N437: Not Run
A438: E2E-GDS-011 | B438: Control Panel | C438: Control Panel — Access control & system | D438: /admin/gates/dashboard | E438: RTL / Arabic render | I438: P1 | J438: i18n | K438: cp-admin-gates-dashboard.md | N438: Not Run
A439: E2E-GOP-001 | B439: Control Panel | C439: Control Panel — Access control & system | D439: /admin/gates/operator | E439: Golden path | I439: P0 | J439: happy | K439: cp-admin-gates-operator.md | N439: Not Run
... A741: E2E-OTH-024 | B741: Control Panel | C741: Control Panel — People & accounts | D741: /admin/others | E741: Full-page mode round-trip (D-353) | I741: P1 | J741: happy | K741: cp-admin-others.md | N741: Not Run
...

Sheet 04 · Website
A1: ID | B1: Surface | C1: Area / Flow | D1: Page / Route | E1: Test (scenario) | F1: Steps / Gherkin | G1: Test data | H1: Expected result | I1: Priority | J1: Type | K1: Catalogue ref | L1: Comment | M1: Time (min) | N1: Status | O1: Developer comment | P1: Evidence
A2: E2E-WNT-001 | B2: Website | C2: Website | D2: /account/notifications | E2: Golden round-trip | I2: P0 | J2: happy | K2: web-account-notifications.md | N2: Not Run
A3: E2E-WNT-002 | B3: Website | C3: Website | D3: /account/notifications | E3: Empty inbox | I3: P1 | J3: happy | K3: web-account-notifications.md | N3: Not Run
A4: E2E-WNT-003 | B4: Website | C4: Website | D4: /account/notifications | E4: Delete one (per-row trash action) | I4: P0 | J4: happy | K4: web-account-notifications.md | N4: Not Run
A5: E2E-WNT-004 | B5: Website | C5: Website | D5: /account/notifications | E5: Mark all as read | I5: P0 | J5: happy | K5: web-account-notifications.md | N5: Not Run
A6: E2E-WNT-005 | B6: Website | C6: Website | D6: /account/notifications | E6: Per-column filter | I6: P1 | J6: happy | K6: web-account-notifications.md | N6: Not Run
A7: E2E-WNT-006 | B7: Website | C7: Website | D7: /account/notifications | E7: Pager | I7: P1 | J7: happy | K7: web-account-notifications.md | N7: Not Run
A8: E2E-WNT-007 | B8: Website | C8: Website | D8: /account/notifications | E8: Column sort | I8: P2 | J8: happy | K8: web-account-notifications.md | N8: Not Run
A9: E2E-WNT-008 | B9: Website | C9: Website | D9: /account/notifications | E9: Auth gate (unauthenticated) | I9: P0 | J9: auth | K9: web-account-notifications.md | N9: Not Run
A10: E2E-WNT-009 | B10: Website | C10: Website | D10: /account/notifications | E10: Per-user isolation | I10: P0 | J10: auth | K10: web-account-notifications.md | N10: Not Run
A11: E2E-WNT-010 | B11: Website | C11: Website | D11: /account/notifications | E11: Idempotent delete | I11: P1 | J11: error | K11: web-account-notifications.md | N11: Not Run
A12: E2E-WNT-011 | B12: Website | C12: Website | D12: /account/notifications | E12: Server 500 on list | I12: P2 | J12: resilience | K12: web-account-notifications.md | N12: Not Run
A13: E2E-WNT-012 | B13: Website | C13: Website | D13: /account/notifications | E13: RTL / Arabic render | I13: P1 | J13: i18n | K13: web-account-notifications.md | N13: Not Run
... A39: E2E-WPR-016 | B39: Website | C39: Website | D39: /account/profile | E39: RTL / Arabic render | I39: P1 | J39: i18n | K39: web-account-profile.md | N39: Not Run
A40: E2E-WPR-017 | B40: Website | C40: Website | D40: /account/profile | E40: Organisation is required + digit-only ID fields (D-354) | I40: P1 | K40: web-account-profile.md | N40: Not Run
A41: E2E-WRJ-001 | B41: Website | C41: Website | D41: /account/rejected | E41: Golden path | I41: P0 | J41: happy | K41: web-account-rejected.md | N41: Not Run
A42: E2E-WRJ-002 | B42: Website | C42: Website | D42: /account/rejected | E42: No-reason fallback | I42: P1 | J42: happy | K42: web-account-rejected.md | N42: Not Run
A43: E2E-WRJ-003 | B43: Website | C43: Website | D43: /account/rejected | E43: Auth gate (anonymous) | I43: P0 | J43: auth | K43: web-account-rejected.md | N43: Not Run
A44: E2E-WRJ-004 | B44: Website | C44: Website | D44: /account/rejected | E44: State-guard redirect: Approved | I44: P0 | J44: redirect | K44: web-account-rejected.md | N44: Not Run
A45: E2E-WRJ-005 | B45: Website | C45: Website | D45: /account/rejected | E45: State-guard redirect: PendingApproval | I45: P1 | J45: redirect | K45: web-account-rejected.md | N45: Not Run
A46: E2E-WRJ-006 | B46: Website | C46: Website | D46: /account/rejected | E46: Sign-out action | I46: P0 | J46: happy | K46: web-account-rejected.md | N46: Not Run
A47: E2E-WRJ-007 | B47: Website | C47: Website | D47: /account/rejected | E47: Sign-out resilience (API failure) | I47: P2 | J47: resilience | K47: web-account-rejected.md | N47: Not Run
A48: E2E-WRJ-008 | B48: Website | C48: Website | D48: /account/rejected | E48: Culture pick (Arabic reason) | I48: P1 | J48: i18n | K48: web-account-rejected.md | N48: Not Run
A49: E2E-WRJ-009 | B49: Website | C49: Website | D49: /account/rejected | E49: RTL render | I49: P1 | J49: i18n | K49: web-account-rejected.md | N49: Not Run
A50: E2E-WRJ-010 | B50: Website | C50: Website | D50: /account/rejected | E50: XSS-safety of the reason text | I50: P2 | J50: security | K50: web-account-rejected.md | N50: Not Run
A51: E2E-WFP-001 | B51: Website | C51: Website | D51: /forgot-password | E51: Golden path (known email → `/reset-password`) | I51: P0 | J51: happy | K51: web-forgot-password.md | N51: Not Run
A52: E2E-WFP-002 | B52: Website | C52: Website | D52: /forgot-password | E52: Anti-enumeration (unknown email behaves identically) | I52: P0 | J52: happy | K52: web-forgot-password.md | N52: Not Run
... A154: E2E-WVS-011 | B154: Website | C154: Website | D154: /visit | E154: RTL / Arabic render | I154: P1 | J154: i18n | K154: web-visit.md | N154: Not Run

Sheet 05 · Mobile App
A1: ID | B1: Surface | C1: Area / Flow | D1: Page / Route | E1: Test (scenario) | F1: Steps / Gherkin | G1: Test data | H1: Expected result | I1: Priority | J1: Type | K1: Catalogue ref | L1: Comment | M1: Time (min) | N1: Status | O1: Developer comment | P1: Evidence
A2: E2E-MOB207-001 | B2: Mobile App | C2: Mobile App (Flutter) | E2: App info + links | I2: P1 | K2: mobile-about-app.md | N2: Not Run
A3: E2E-MOB207-002 | B3: Mobile App | C3: Mobile App (Flutter) | E3: Support contact from the org profile | I3: P1 | K3: mobile-about-app.md | N3: Not Run
A4: E2E-MOB207-003 | B4: Mobile App | C4: Mobile App (Flutter) | E4: Public reachability | I4: P1 | K4: mobile-about-app.md | N4: Not Run
A5: E2E-MOB207-004 | B5: Mobile App | C5: Mobile App (Flutter) | E5: Manual check: up to date (D-736) | I5: P1 | K5: mobile-about-app.md | N5: Not Run
A6: E2E-MOB207-005 | B6: Mobile App | C6: Mobile App (Flutter) | E6: Manual check: update available → store (D-736) | I6: P1 | K6: mobile-about-app.md | N6: Not Run
A7: E2E-MOB207-006 | B7: Mobile App | C7: Mobile App (Flutter) | E7: Manual check: honest network error (D-736) | I7: P1 | K7: mobile-about-app.md | N7: Not Run
A8: E2E-MOB037-001 | B8: Mobile App | C8: Mobile App (Flutter) | D8: GET /api/v1/app/content/about` · app screen #37 `/about | E8: About content + themes | I8: P0 | J8: happy | K8: mobile-about.md | N8: Not Run
A9: E2E-MOB037-002 | B9: Mobile App | C9: Mobile App (Flutter) | D9: GET /api/v1/app/content/about` · app screen #37 `/about | E9: Unseeded key (404) → static fallback paragraph; themes still render | I9: P1 | J9: edge | K9: mobile-about.md | N9: Not Run
A10: E2E-MOB037-003 | B10: Mobile App | C10: Mobile App (Flutter) | D10: GET /api/v1/app/content/about` · app screen #37 `/about | E10: Server error → degrades to static content (no error screen) | I10: P1 | J10: edge | K10: mobile-about.md | N10: Not Run
A11: E2E-MOB037-004 | B11: Mobile App | C11: Mobile App (Flutter) | D11: GET /api/v1/app/content/about` · app screen #37 `/about | E11: RTL: the theme number sits to the right (inline start) of its title | I11: P1 | J11: rtl | K11: mobile-about.md | N11: Not Run
A12: E2E-MOB038-001 | B12: Mobile App | C12: Mobile App (Flutter) | D12: app screen #38 `/settings/accessibility` (no API) | E12: Both sections render: 4 font chips + 4 switches | I12: P0 | J12: happy | K12: mobile-accessibility.md | N12: Not Run
A13: E2E-MOB038-002 | B13: Mobile App | C13: Mobile App (Flutter) | D13: app screen #38 `/settings/accessibility` (no API) | E13: Toggling high-contrast flips it and persists | I13: P0 | J13: happy | K13: mobile-accessibility.md | N13: Not Run
A14: E2E-MOB038-003 | B14: Mobile App | C14: Mobile App (Flutter) | D14: app screen #38 `/settings/accessibility` (no API) | E14: Picking a text size (أكبر) persists `extraLarge` | I14: P1 | J14: happy | K14: mobile-accessibility.md | N14: Not Run
A15: E2E-MOB038-004 | B15: Mobile App | C15: Mobile App (Flutter) | D15: app screen #38 `/settings/accessibility` (no API) | E15: Screen-reader assist defaults off, persists on | I15: P1 | J15: happy | K15: mobile-accessibility.md | N15: Not Run
A16: E2E-MOB038-005 | B16: Mobile App | C16: Mobile App (Flutter) | D16: app screen #38 `/settings/accessibility` (no API) | E16: Captions default on, persist off → live strip hidden | I16: P1 | J16: happy | K16: mobile-accessibility.md | N16: Not Run
A17: E2E-MOB038-006 | B17: Mobile App | C17: Mobile App (Flutter) | D17: app screen #38 `/settings/accessibility` (no API) | E17: Choices persisted to prefs + applied app-wide (scale / contrast / motion) | I17: P1 | J17: happy | K17: mobile-accessibility.md | N17: Not Run
A18: E2E-MOB016-001 | B18: Mobile App | C18: Mobile App (Flutter) | E18: Anonymous full programme | I18: P0 | J18: happy | K18: mobile-agenda.md | N18: Not Run
A19: E2E-MOB016-002 | B19: Mobile App | C19: Mobile App (Flutter) | E19: Cached payload carries body + speakers (D-252) | I19: P0 | J19: happy | K19: mobile-agenda.md | N19: Not Run
A20: E2E-MOB016-003 | B20: Mobile App | C20: Mobile App (Flutter) | E20: Ordering | I20: P1 | J20: happy | K20: mobile-agenda.md | N20: Not Run
A21: E2E-MOB016-004 | B21: Mobile App | C21: Mobile App (Flutter) | E21: Day filter (thin client) | I21: P1 | J21: happy | K21: mobile-agenda.md | N21: Not Run
A22: E2E-MOB016-005 | B22: Mobile App | C22: Mobile App (Flutter) | E22: Malformed day | I22: P1 | J22: error | K22: mobile-agenda.md | N22: Not Run
A23: E2E-MOB016-006 | B23: Mobile App | C23: Mobile App (Flutter) | E23: Soft-delete drops from list | I23: P1 | J23: edge | K23: mobile-agenda.md | N23: Not Run
A24: E2E-MOB016-007 | B24: Mobile App | C24: Mobile App (Flutter) | E24: Tap-through + type tag | I24: P1 | J24: happy | K24: mobile-agenda.md | N24: Not Run
A25: E2E-MOB016-008 | B25: Mobile App | C25: Mobile App (Flutter) | E25: Client-side filters, no refetch | I25: P0 | J25: happy | K25: mobile-agenda.md | N25: Not Run
A26: E2E-MOB016-009 | B26: Mobile App | C26: Mobile App (Flutter) | E26: RTL render | I26: P1 | J26: i18n | K26: mobile-agenda.md | N26: Not Run
A27: E2E-MOB016-010 | B27: Mobile App | C27: Mobile App (Flutter) | E27: Empty state | I27: P1 | J27: edge | K27: mobile-agenda.md | N27: Not Run
A28: E2E-MOB016-011 | B28: Mobile App | C28: Mobile App (Flutter) | E28: Error + retry | I28: P0 | J28: resilience | K28: mobile-agenda.md | N28: Not Run
A29: E2E-MOB016-012 | B29: Mobile App | C29: Mobile App (Flutter) | E29: Tolerant enum decode (int wire, D-299) | I29: P0 | J29: contract | K29: mobile-agenda.md | N29: Not Run
... A33: E2E-MOB016-016 | B33: Mobile App | C33: Mobile App (Flutter) | E33: **Time-rail from→to connector (D-705):** every المواعيد row shows the vertical beige line between its start and end time — including a **collapsed/short row** (title only, no banner/description) where it previously collapsed to zero (Figma 1310:3243/3244) | I33: P1 | J33: visual | K33: mobile-agenda.md | N33: Not Run
A34: E2E-MOB034-001 | B34: Mobile App | C34: Mobile App (Flutter) | D34: GET /api/v1/app/programme/sessions/{id}/summary` (+ `…/sessions` for the picker) · app screen #34 `/ai-summary?sessionId={id} | E34: **Details-only when opened with a `sessionId` (#1/#6):** no picker; AI banner + the three stacked cards (all content at once, no tabs) + action row | I34: P0 | J34: happy | K34: mobile-ai-summary.md | N34: Not Run
A35: E2E-MOB034-002 | B35: Mobile App | C35: Mobile App (Flutter) | D35: GET /api/v1/app/programme/sessions/{id}/summary` (+ `…/sessions` for the picker) · app screen #34 `/ai-summary?sessionId={id} | E35: Speakers render as a single "·"-joined line | I35: P1 | J35: happy | K35: mobile-ai-summary.md | N35: Not Run
A36: E2E-MOB034-003 | B36: Mobile App | C36: Mobile App (Flutter) | D36: GET /api/v1/app/programme/sessions/{id}/summary` (+ `…/sessions` for the picker) · app screen #34 `/ai-summary?sessionId={id} | E36: **No `sessionId` → the picker is shown** (legacy fallback) + auto-select the first session | I36: P1 | J36: happy | K36: mobile-ai-summary.md | N36: Not Run
A37: E2E-MOB034-004 | B37: Mobile App | C37: Mobile App (Flutter) | D37: GET /api/v1/app/programme/sessions/{id}/summary` (+ `…/sessions` for the picker) · app screen #34 `/ai-summary?sessionId={id} | E37: 404 → no-published-summary state; **no picker in details-only** (the user goes back to the list to pick another) | I37: P1 | J37: edge | K37: mobile-ai-summary.md | N37: Not Run
A38: E2E-MOB034-005 | B38: Mobile App | C38: Mobile App (Flutter) | D38: GET /api/v1/app/programme/sessions/{id}/summary` (+ `…/sessions` for the picker) · app screen #34 `/ai-summary?sessionId={id} | E38: Non-404 failure → error + retry, which re-fetches | I38: P1 | J38: edge | K38: mobile-ai-summary.md | N38: Not Run
A39: E2E-MOB034-006 | B39: Mobile App | C39: Mobile App (Flutter) | D39: GET /api/v1/app/programme/sessions/{id}/summary` (+ `…/sessions` for the picker) · app screen #34 `/ai-summary?sessionId={id} | E39: **Summaries LIST (#1/#6):** the home "ملخص الجلسات" tile opens `SessionSummaryListScreen` — a list of all sessions (title + time · hall); tapping one opens the AI-summary details (sessionId in query). Empty → empty state | I39: P1 | J39: happy | K39: mobile-ai-summary.md | N39: Not Run
A40: E2E-MOB024D-001 | B40: Mobile App | C40: Mobile App (Flutter) | D40: GET /api/v1/app/archive/{id}` (anonymous) · app screen #24-01 `/archive/:editionId` *(planned — not yet in `route_names.dart`)* (public) | E40: Detail returned for a visible edition | I40: P0 | J40: happy | K40: mobile-archive-detail.md | N40: Not Run
A41: E2E-MOB024D-002 | B41: Mobile App | C41: Mobile App (Flutter) | D41: GET /api/v1/app/archive/{id}` (anonymous) · app screen #24-01 `/archive/:editionId` *(planned — not yet in `route_names.dart`)* (public) | E41: Place + date label round-trip | I41: P0 | J41: happy | K41: mobile-archive-detail.md | N41: Not Run
A42: E2E-MOB024D-003 | B42: Mobile App | C42: Mobile App (Flutter) | D42: GET /api/v1/app/archive/{id}` (anonymous) · app screen #24-01 `/archive/:editionId` *(planned — not yet in `route_names.dart`)* (public) | E42: Anonymous read | I42: P0 | J42: auth | K42: mobile-archive-detail.md | N42: Not Run
A43: E2E-MOB024D-004 | B43: Mobile App | C43: Mobile App (Flutter) | D43: GET /api/v1/app/archive/{id}` (anonymous) · app screen #24-01 `/archive/:editionId` *(planned — not yet in `route_names.dart`)* (public) | E43: Unknown id | I43: P0 | J43: edge | K43: mobile-archive-detail.md | N43: Not Run
...

Sheet 06 · Cross-cutting
A1: ID | B1: Surface | C1: Area / Flow | D1: Page / Route | E1: Test (scenario) | F1: Steps / Gherkin | G1: Test data | H1: Expected result | I1: Priority | J1: Type | K1: Catalogue ref | L1: Comment | M1: Time (min) | N1: Status | O1: Developer comment | P1: Evidence
A2: E2E-BF-10-001 | B2: CP | C2: BF-10 Full Control-Panel smoke — no dead button, no crash, permission gate | E2: Golden sweep — Administrator drives every ✅ Real route; each renders, no error boundary, zero console errors | F2: Feature: Full Control-Panel smoke sweep As a production-readiness tester I want to open every real CP page as an Administrator So that I prove no page throws, no console errors, and nothing is dead Background: Given the API is reachable on http://localhost:5175 And the Control Panel is reachable on http://localhost:5158 And an Administrator is signed in (password + TOTP via the Get-Totp helper) Scenario: Drive every ✅ Real route from PAGE-INDEX Given the list of ✅ Real CP routes is read from docs/pages/PAGE-INDEX.md (the "/" dashboard plus every /admin/* row marked ✅ Real) When the tester navigates to each route in turn | route (examples) | | / | | /admin/sessions | | /admin/speakers | | /admin/sponsors | | /admin/roles | | /admin/visitors | | /admin/organisations | | /admin/programme-days | | /admin/configuration | | /admin/email/templates | Then each page reaches HTTP 200 and renders its SimfBanner / page header And no Blazor error-boundary ("An unhandled error has occurred") appears And the browser console shows zero errors on each page And the network list shows zero failed assets (no 404 img/css/js) And a DOM check confirms scrollWidth == clientWidth (no horizontal overflow) | I2: P0 | J2: happy | K2: SIMF-Business-Flows.md | N2: Not Run
A3: E2E-BF-10-002 | B3: CP | C3: BF-10 Full Control-Panel smoke — no dead button, no crash, permission gate | E3: Every list page is a `SimfDataGrid` (filter + sort + select-all + row checkbox + quiet icon actions) | F3: Scenario: Every CP list page is a SimfDataGrid, not a raw table Given the Administrator opens each list route in the sweep (e.g. /admin/sessions, /admin/speakers, /admin/sponsors, /admin/roles, /admin/visitors) Then the page renders a SimfDataGrid (not a bare <table>) And the grid exposes a per-column filter row And each sortable column header toggles ascending / descending And a select-all header checkbox selects every visible row And each row carries its own selection checkbox And row actions are quiet icon buttons (edit / delete / view), not text buttons And server-side paging works: changing the page fetches the next slice | I3: P1 | J3: happy | K3: SIMF-Business-Flows.md | N3: Not Run
A4: E2E-BF-10-003 | B4: CP | C4: BF-10 Full Control-Panel smoke — no dead button, no crash, permission gate | E4: Primary action buttons are enabled and do something (open a working create dialog — not dead) | F4: Scenario: The page's primary action button is enabled and does something Given the Administrator is on /admin/speakers And the header shows the primary action "Add speaker" wrapped in <AuthorizedAction> When they click "Add speaker" Then the create dialog / form opens (the button is not inert) And every field is a real bound input (SimfTextField with @bind-Value, dropdowns populated) When the tester repeats this for the primary action on each list route in the sweep Then no primary action button is disabled-without-cause or a no-op | I4: P0 | J4: happy | K4: SIMF-Business-Flows.md | N4: Not Run
A5: E2E-BF-10-004 | B5: CP | C5: BF-10 Full Control-Panel smoke — no dead button, no crash, permission gate | E5: Required-field validation blocks a create submit with a bilingual `SimfAlert` | F5: Scenario: Submitting a create form empty is blocked with a bilingual alert Given the Administrator has opened the "Add speaker" dialog on /admin/speakers When they click "Save" with the required Name / NameArabic fields left blank Then the form does not submit And a bilingual SimfAlert (validation) appears listing the missing required fields And the FluentValidation MaximumLength matches the EF HasMaxLength and the UI MaxLength (the validation triple-lock — over-long input is rejected the same way on all three) And no row is created (the grid count is unchanged) | I5: P1 | J5: error | K5: SIMF-Business-Flows.md | N5: Not Run
A6: E2E-BF-10-005 | B6: CP | C6: BF-10 Full Control-Panel smoke — no dead button, no crash, permission gate | E6: Empty list renders `SimfEmptyState` with bilingual copy, no error toast | F6: Scenario: An empty list shows SimfEmptyState, not a broken grid Given a list surface has zero rows (e.g. /admin/media-partners on a fresh DB) When the Administrator opens the page Then the grid area renders the shared SimfEmptyState component And its copy is bilingual (English + Arabic) And no error toast and no error boundary appears And the primary "Add …" action is still enabled so the list can be populated | I6: P1 | J6: happy | K6: SIMF-Business-Flows.md | N6: Not Run
A7: E2E-BF-10-006 | B7: CP | C7: BF-10 Full Control-Panel smoke — no dead button, no crash, permission gate | E7: Permission gate — a role lacking the page permission is redirected to `/not-permitted` (HTTP 200) | F7: Scenario: A signed-in role lacking the page permission is denied Given a custom CP role "ProgrammeEditor" exists that holds Sessions.View but does NOT hold Roles.View And a user in that role is signed in (not an Administrator) When they navigate directly to /admin/roles Then RequirePermissionAttribute denies access And the browser is redirected to /not-permitted with HTTP 200 (the AccessDeniedPath configured in Program.cs) And the /not-permitted page renders (no raw 403 body, no error boundary) When the same user navigates to /admin/sessions (they hold Sessions.View) Then the page renders normally | I7: P0 | J7: auth | K7: SIMF-Business-Flows.md | N7: Not Run
A8: E2E-BF-10-007 | B8: CP | C8: BF-10 Full Control-Panel smoke — no dead button, no crash, permission gate | E8: Administrator wildcard `"*"` reaches every ✅ Real route (no false 403) | F8: Scenario: Administrator's "*" wildcard opens every real page Given an Administrator is signed in And their perm claim carries the wildcard PermissionCatalog.Wildcard ("*") When they drive every ✅ Real route in the sweep Then no route ever redirects them to /not-permitted And every page the sweep visits renders (the wildcard satisfies each RequirePermission check) | I8: P1 | J8: auth | K8: SIMF-Business-Flows.md | N8: Not Run
A9: E2E-BF-10-008 | B9: CP | C9: BF-10 Full Control-Panel smoke — no dead button, no crash, permission gate | E9: Side-nav is permission-filtered — items whose `RequiredPermission` the role lacks are hidden | F9: Scenario: The side menu only shows items the role may reach Given the "ProgrammeEditor" role (holds Sessions.View, lacks Roles.View / Admins.View) is signed in When the CP shell renders the navigation Then CpNavigation items whose RequiredPermission the role lacks are hidden (e.g. "Roles" and "Admins" do not appear in the menu) And items the role holds (e.g. "Sessions") do appear And the dashboard "/" (RequiredPermission = null) is always visible | I9: P1 | J9: auth | K9: SIMF-Business-Flows.md | N9: Not Run
A10: E2E-BF-10-009 | B10: CP | C10: BF-10 Full Control-Panel smoke — no dead button, no crash, permission gate | E10: API gate parity — the list endpoint returns HTTP 403 for the same role the CP redirects | F10: Scenario: The admin endpoint denies the same role the CP redirects Given the "ProgrammeEditor" role lacks Roles.View And its bearer token is minted with only the codes it holds When it calls the admin list endpoint behind /admin/roles (gated with Policies(PermissionCatalog.PolicyFor(PermissionCatalog.Roles.View))) Then the API responds HTTP 403 Forbidden And the ApiResult<T> envelope carries the failure (no data leaked) When an Administrator (wildcard) calls the same endpoint Then it responds HTTP 200 with the paged ApiResult<T> payload | I10: P0 | J10: auth | K10: SIMF-Business-Flows.md | N10: Not Run
A11: E2E-BF-10-010 | B11: CP | C11: BF-10 Full Control-Panel smoke — no dead button, no crash, permission gate | E11: Build guards fail if a page/endpoint gate is missing (`CpNavigationPermissionTests` + `PermissionEnforcementTests`) | F11: Scenario: A page or endpoint with no permission gate fails the build Given a new CP page is added under /admin without an @attribute [RequirePermission(...)] When the solution is built and the test suite runs Then CpNavigationPermissionTests fails (the page / nav item has no RequiredPermission) And when a new admin endpoint ships without Policies(PermissionCatalog.PolicyFor(...)) Then PermissionEnforcementTests fails And the missing gate is treated as a security defect, not a warning # An ungated admin page/endpoint is reachable by ANY signed-in admin regardless of role. | I11: P1 | J11: resilience | K11: SIMF-Business-Flows.md | N11: Not Run
A12: E2E-BF-10-011 | B12: CP | C12: BF-10 Full Control-Panel smoke — no dead button, no crash, permission gate | E12: D-648 render-trap guard — no CP `SimfTextField` without `ValueExpression` (page freeze) | F12: Scenario: No CP SimfTextField is left without a ValueExpression Given the CP uses the shared SimfTextField component When any page renders a SimfTextField that has neither @bind-Value nor ValueExpression (or is marked Numeric=true without a ValueExpression) Then that page FREEZES mid-render (blank / spinner that never resolves) — the D-648 trap Therefore during the sweep every text page (e.g. the create/edit dialogs on /admin/sessions, /admin/speakers, /admin/configuration) is opened and asserted to finish rendering (form fields interactive) within the normal load budget And any page that hangs on open is flagged as a D-648 regression | I12: P1 | J12: resilience | K12: SIMF-Business-Flows.md | N12: Not Run
A13: E2E-BF-10-012 | B13: CP | C13: BF-10 Full Control-Panel smoke — no dead button, no crash, permission gate | E13: Server 500 on page load renders an error surface, not a blank white crash | F13: Scenario: A backend 500 on load shows an error surface, not a white crash Given the admin API for a page returns HTTP 500 (simulated backend fault) When the Administrator opens that page Then the page renders a bilingual error surface (SimfAlert / SimfEmptyState error variant) And it is not a blank white screen and not an unhandled Blazor error boundary And a retry / reload affordance is available And the console records the handled failure without an uncaught exception | I13: P2 | J13: resilience | K13: SIMF-Business-Flows.md | N13: Not Run
... A80: E2E-BF-15-013 | B80: App | C80: BF-15 Notification-kind → icon / group / deep-link inventory | E80: RTL render: the Arabic notifications screen mirrors correctly | F80: Scenario: The Arabic notifications screen mirrors correctly Given the app language is Arabic (the primary language, RTL) When the visitor opens /notifications Then the header title reads "الإشعارات" and the back affordance sits on the right And the الكل / جلسات / VIP chips lay out right-to-left And each row's category icon, title, body, and unread dot mirror to the RTL edge And the day groupings render as اليوم / أمس / date And scrollWidth == clientWidth (no horizontal overflow) | I80: P1 | J80: i18n | K80: SIMF-Business-Flows.md | N80: Not Run

Sheet 07 · Defect log
A1: Defect ID | B1: Date | C1: Source scenario / flow ID | D1: Surface | E1: Severity | F1: Title | G1: Steps to reproduce | H1: Expected | I1: Actual | J1: Root cause | K1: Fix commit | L1: Regression test | M1: Status
